[MFLOG|0|2023-09-08T17:02:26.133896Z|runtime|9eb5ce7a-b69e-44c2-8dd8-8012bffd8f0a]<flow Flow step load_data> failed:
[MFLOG|0|2023-09-08T17:02:26.138119Z|runtime|3c62d7ee-9827-43ee-9381-6ddd74ff05a9]    Internal error
[MFLOG|0|2023-09-08T17:02:26.138987Z|runtime|679a0e31-2acd-4710-9ab1-cf37c05c971d]Traceback (most recent call last):
[MFLOG|0|2023-09-08T17:02:26.139130Z|runtime|b11a9d83-426a-4c85-9b8c-c655200a763e]  File "/home/gehlot/Documents/lamlp/lamlp/lib/python3.10/site-packages/metaflow/cli.py", line 1172, in main
[MFLOG|0|2023-09-08T17:02:26.139224Z|runtime|725d335c-6b3d-4466-a24f-9f71a0fba3f8]    start(auto_envvar_prefix="METAFLOW", obj=state)
[MFLOG|0|2023-09-08T17:02:26.139311Z|runtime|5495f6d6-3ccb-4711-8e3b-e7fb6fa9fd65]  File "/home/gehlot/Documents/lamlp/lamlp/lib/python3.10/site-packages/metaflow/_vendor/click/core.py", line 829, in __call__
[MFLOG|0|2023-09-08T17:02:26.139398Z|runtime|cf402eb5-1ed5-4dcc-bff0-9a1b66ed6698]    return self.main(args, kwargs)
[MFLOG|0|2023-09-08T17:02:26.352374Z|runtime|1857d875-3e9d-4c0d-8d56-3d5e962e101c]  File "/home/gehlot/Documents/lamlp/lamlp/lib/python3.10/site-packages/metaflow/_vendor/click/core.py", line 782, in main
[MFLOG|0|2023-09-08T17:02:26.352551Z|runtime|13bd7e5f-0525-4a31-bed7-cbaf2a6820e2]    rv = self.invoke(ctx)
[MFLOG|0|2023-09-08T17:02:26.352659Z|runtime|fc8da794-6413-4b0e-a497-27f1c77e207e]  File "/home/gehlot/Documents/lamlp/lamlp/lib/python3.10/site-packages/metaflow/_vendor/click/core.py", line 1259, in invoke
[MFLOG|0|2023-09-08T17:02:26.352763Z|runtime|8510be89-9985-48b5-b204-4c2cd117d8fd]    return _process_result(sub_ctx.command.invoke(sub_ctx))
[MFLOG|0|2023-09-08T17:02:26.352871Z|runtime|b8bf934e-b9ef-45ec-b775-48ebc1788297]  File "/home/gehlot/Documents/lamlp/lamlp/lib/python3.10/site-packages/metaflow/_vendor/click/core.py", line 1066, in invoke
[MFLOG|0|2023-09-08T17:02:26.352985Z|runtime|f78d22d6-4895-48e0-9b85-209504fc8d0c]    return ctx.invoke(self.callback, ctx.params)
[MFLOG|0|2023-09-08T17:02:26.353105Z|runtime|6da34b2a-f452-4db7-bdbc-1d146f51f157]  File "/home/gehlot/Documents/lamlp/lamlp/lib/python3.10/site-packages/metaflow/_vendor/click/core.py", line 610, in invoke
[MFLOG|0|2023-09-08T17:02:26.353218Z|runtime|51e638c8-46f4-48ec-9e32-b03e5ff1a2ae]    return callback(args, kwargs)
[MFLOG|0|2023-09-08T17:02:26.353329Z|runtime|651448e6-3867-4324-a37c-66bba12c14c1]  File "/home/gehlot/Documents/lamlp/lamlp/lib/python3.10/site-packages/metaflow/_vendor/click/decorators.py", line 21, in new_func
[MFLOG|0|2023-09-08T17:02:26.353438Z|runtime|c9fa151f-ade3-4f34-8353-e2eaf23d1f3d]    return f(get_current_context(), args, kwargs)
[MFLOG|0|2023-09-08T17:02:26.353547Z|runtime|3c4e750e-b5b7-41e6-95e8-f26bac68682c]  File "/home/gehlot/Documents/lamlp/lamlp/lib/python3.10/site-packages/metaflow/cli.py", line 581, in step
[MFLOG|0|2023-09-08T17:02:26.353652Z|runtime|ec52e2c9-9c4d-4e9b-8993-14523915b3d2]    task.run_step(
[MFLOG|0|2023-09-08T17:02:26.353761Z|runtime|b956a706-e313-486d-ac5d-39af112d0d47]  File "/home/gehlot/Documents/lamlp/lamlp/lib/python3.10/site-packages/metaflow/task.py", line 583, in run_step
[MFLOG|0|2023-09-08T17:02:26.353866Z|runtime|b9907e34-d415-470d-b21c-34cee69ef7b8]    self._exec_step_function(step_func)
[MFLOG|0|2023-09-08T17:02:26.353976Z|runtime|06734b6d-c0ce-49c6-8bb3-fbb8ecec3d7d]  File "/home/gehlot/Documents/lamlp/lamlp/lib/python3.10/site-packages/metaflow/task.py", line 57, in _exec_step_function
[MFLOG|0|2023-09-08T17:02:26.354098Z|runtime|0fb8992f-58e4-44a1-86fa-a73521773a75]    step_function()
[MFLOG|0|2023-09-08T17:02:26.354199Z|runtime|3d5bc114-c89b-4f7a-84a3-3e56dd7190e5]  File "/home/gehlot/Documents/lamlp/Loan-Approval-Machine-Learning-Project/metaflow/flow.py", line 13, in load_data
[MFLOG|0|2023-09-08T17:02:26.354298Z|runtime|5aa9effa-acd3-4f9e-b5d2-12357fc037ba]    self.data = pd.read_csv('../data/loan_data.csv')
[MFLOG|0|2023-09-08T17:02:26.354399Z|runtime|3018c885-2e1a-4f64-84bc-bbe5bea81c3a]  File "/home/gehlot/Documents/lamlp/lamlp/lib/python3.10/site-packages/pandas/io/parsers/readers.py", line 948, in read_csv
[MFLOG|0|2023-09-08T17:02:26.354496Z|runtime|3953c8e8-9a2b-4041-8b69-e2eca58a58d1]    return _read(filepath_or_buffer, kwds)
[MFLOG|0|2023-09-08T17:02:26.354596Z|runtime|529897cf-6003-4a6b-a58a-0477ed76b9a2]  File "/home/gehlot/Documents/lamlp/lamlp/lib/python3.10/site-packages/pandas/io/parsers/readers.py", line 611, in _read
[MFLOG|0|2023-09-08T17:02:26.354694Z|runtime|1edf47df-7cbb-475a-a044-917ebd3f685e]    parser = TextFileReader(filepath_or_buffer, kwds)
[MFLOG|0|2023-09-08T17:02:26.354796Z|runtime|5cad2f16-ef2c-47f6-bf0d-2ab4baeb0df9]  File "/home/gehlot/Documents/lamlp/lamlp/lib/python3.10/site-packages/pandas/io/parsers/readers.py", line 1448, in __init__
[MFLOG|0|2023-09-08T17:02:26.354894Z|runtime|c17fde69-f2b5-4c1b-bdd3-f7d2a04fa885]    self._engine = self._make_engine(f, self.engine)
[MFLOG|0|2023-09-08T17:02:26.354991Z|runtime|f47615ff-c3be-44d6-9d4f-8624702d7483]  File "/home/gehlot/Documents/lamlp/lamlp/lib/python3.10/site-packages/pandas/io/parsers/readers.py", line 1705, in _make_engine
[MFLOG|0|2023-09-08T17:02:26.355092Z|runtime|83740d85-23b3-4376-b941-b853854f278b]    self.handles = get_handle(
[MFLOG|0|2023-09-08T17:02:26.355192Z|runtime|4bfccb48-6b9c-4f06-893b-a217d8297d9d]  File "/home/gehlot/Documents/lamlp/lamlp/lib/python3.10/site-packages/pandas/io/common.py", line 863, in get_handle
[MFLOG|0|2023-09-08T17:02:26.355290Z|runtime|b1c4b8e4-cd15-484d-b13d-c06234cb170f]    handle = open(
[MFLOG|0|2023-09-08T17:02:26.355389Z|runtime|6c7f33d5-0055-4901-8693-a148120faa84]FileNotFoundError: [Errno 2] No such file or directory: '../data/loan_data.csv'
[MFLOG|0|2023-09-08T17:02:26.355488Z|runtime|7f476f99-dafe-48e2-b736-b4a9197d74f6]
[MFLOG|0|2023-09-08T17:02:26.355820Z|runtime|44a6081b-26b7-468b-8f88-250596f7d54f]Task failed.